<?xml version="1.0" ?>
<!-- =================================================================================== -->
<!-- |    This document was autogenerated by xacro from al5d_cad.xacro                 | -->
<!-- |    EDITING THIS FILE BY HAND IS NOT RECOMMENDED                                 | -->
<!-- =================================================================================== -->
<robot name="al5d">
  <!-- transmissions are required by the controller manager (here: for simulation in gazebo) -->
  <transmission name="base_rotate_trans">
    <type>transmission_interface/SimpleTransmission</type>
    <joint name="base_rotate">
      <hardwareInterface>hardware_interface/EffortJointInterface</hardwareInterface>
    </joint>
    <actuator name="base_rotate_motor">
      <hardwareInterface>hardware_interface/EffortJointInterface</hardwareInterface>
      <mechanicalReduction>1</mechanicalReduction>
    </actuator>
  </transmission>
  <transmission name="shoulder_tilt_trans">
    <type>transmission_interface/SimpleTransmission</type>
    <joint name="shoulder_tilt">
      <hardwareInterface>hardware_interface/EffortJointInterface</hardwareInterface>
    </joint>
    <actuator name="shoulder_tilt_motor">
      <hardwareInterface>hardware_interface/EffortJointInterface</hardwareInterface>
      <mechanicalReduction>1</mechanicalReduction>
    </actuator>
  </transmission>
  <transmission name="elbow_tilt_trans">
    <type>transmission_interface/SimpleTransmission</type>
    <joint name="elbow_tilt">
      <hardwareInterface>hardware_interface/EffortJointInterface</hardwareInterface>
    </joint>
    <actuator name="elbow_tilt_motor">
      <hardwareInterface>hardware_interface/EffortJointInterface</hardwareInterface>
      <mechanicalReduction>1</mechanicalReduction>
    </actuator>
  </transmission>
  <transmission name="wrist_tilt_trans">
    <type>transmission_interface/SimpleTransmission</type>
    <joint name="wrist_tilt">
      <hardwareInterface>hardware_interface/EffortJointInterface</hardwareInterface>
    </joint>
    <actuator name="wrist_tilt_motor">
      <hardwareInterface>hardware_interface/EffortJointInterface</hardwareInterface>
      <mechanicalReduction>1</mechanicalReduction>
    </actuator>
  </transmission>
  <transmission name="wrist_rotate_trans">
    <type>transmission_interface/SimpleTransmission</type>
    <joint name="wrist_rotate">
      <hardwareInterface>hardware_interface/EffortJointInterface</hardwareInterface>
    </joint>
    <actuator name="wrist_rotate_motor">
      <hardwareInterface>hardware_interface/EffortJointInterface</hardwareInterface>
      <mechanicalReduction>1</mechanicalReduction>
    </actuator>
  </transmission>
  <transmission name="open_gripperright_trans">
    <type>transmission_interface/SimpleTransmission</type>
    <joint name="open_gripperright">
      <hardwareInterface>hardware_interface/EffortJointInterface</hardwareInterface>
    </joint>
    <actuator name="open_gripperright_motor">
      <hardwareInterface>hardware_interface/EffortJointInterface</hardwareInterface>
      <mechanicalReduction>1</mechanicalReduction>
    </actuator>
  </transmission>
  <transmission name="open_gripperleft_trans">
    <type>transmission_interface/SimpleTransmission</type>
    <joint name="open_gripperleft">
      <hardwareInterface>hardware_interface/EffortJointInterface</hardwareInterface>
    </joint>
    <actuator name="open_gripperleft_motor">
      <hardwareInterface>hardware_interface/EffortJointInterface</hardwareInterface>
      <mechanicalReduction>1</mechanicalReduction>
    </actuator>
  </transmission>
  <link name="world"/>
  <link name="base">
    <visual>
      <origin rpy="0 0 0" xyz="0 0 0.0266"/>
      <geometry>
        <cylinder length=".0532" radius="0.048"/>
      </geometry>
    </visual>
    <collision>
      <origin rpy="0 0 0" xyz="0 0 0.0266"/>
      <geometry>
        <cylinder length=".0532" radius="0.048"/>
      </geometry>
    </collision>
    <inertial>
      <mass value="0.3"/>
      <inertia ixx="0.001" ixy="0.0" ixz="0.0" iyy="0.001" iyz="0.0" izz="0.001"/>
    </inertial>
  </link>
  <link name="upper_base">
    <visual>
      <origin rpy="0 0 0" xyz="0 0 .0582"/>
      <geometry>
        <cylinder length=".004" radius="0.048"/>
      </geometry>
    </visual>
    <visual>
      <origin rpy="0 0 0" xyz="-.01487 0 .0752"/>
      <geometry>
        <box size=".06985 .0508 .030"/>
      </geometry>
    </visual>
    <collision>
      <origin rpy="0 0 0" xyz="0 0 .0582"/>
      <geometry>
        <cylinder length=".004" radius="0.048"/>
      </geometry>
    </collision>
    <collision>
      <origin rpy="0 0 0" xyz="-.01487 0 .0752"/>
      <geometry>
        <box size=".06985 .0508 .030"/>
      </geometry>
    </collision>
    <inertial>
      <mass value="0.3"/>
      <inertia ixx="0.001" ixy="0.0" ixz="0.0" iyy="0.001" iyz="0.0" izz="0.001"/>
    </inertial>
  </link>
  <link name="upper_arm">
    <visual>
      <geometry>
        <mesh filename="package://al5d_description/mesh/upper_arm/UpperArm - Bracket-1.STL"/>
      </geometry>
    </visual>
    <visual>
      <geometry>
        <mesh filename="package://al5d_description/mesh/upper_arm/UpperArm - Bracket-2.STL"/>
      </geometry>
    </visual>
    <collision>
      <origin rpy="0 0 0" xyz="0.073025 0 0"/>
      <geometry>
        <box size=".02 .020 .068"/>
      </geometry>
    </collision>
    <collision>
      <origin rpy="0 0 0" xyz="0.073025 0 .033"/>
      <geometry>
        <box size=".166 .020 .002"/>
      </geometry>
    </collision>
    <collision>
      <origin rpy="0 0 0" xyz="0.073025 0 -.033"/>
      <geometry>
        <box size=".166 .020 .002"/>
      </geometry>
    </collision>
    <inertial>
      <mass value="0.3"/>
      <inertia ixx="0.001" ixy="0.0" ixz="0.0" iyy="0.001" iyz="0.0" izz="0.001"/>
    </inertial>
  </link>
  <link name="lower_arm">
    <visual>
      <origin rpy="0 1.57079 0" xyz="0.0936625 0 0"/>
      <geometry>
        <cylinder length="0.187325" radius=".00635"/>
      </geometry>
    </visual>
    <visual>
      <origin rpy="0 0 0" xyz="-.01982 0 0"/>
      <geometry>
        <box size=".06985 .030 .0508"/>
      </geometry>
    </visual>
    <visual>
      <origin rpy="0 0 0" xyz=".1759 0 0"/>
      <geometry>
        <box size=".0508 .0279 .0381"/>
      </geometry>
    </visual>
    <collision>
      <origin rpy="0 1.57079 0" xyz="0.0936625 0 0"/>
      <geometry>
        <cylinder length="0.187325" radius=".00635"/>
      </geometry>
    </collision>
    <collision>
      <origin rpy="0 0 0" xyz="-.01982 0 0"/>
      <geometry>
        <box size=".06985 .030 .0508"/>
      </geometry>
    </collision>
    <collision>
      <origin rpy="0 0 0" xyz=".1759 0 0"/>
      <geometry>
        <box size=".0508 .0279 .0381"/>
      </geometry>
    </collision>
    <inertial>
      <mass value="0.3"/>
      <inertia ixx="0.001" ixy="0.0" ixz="0.0" iyy="0.001" iyz="0.0" izz="0.001"/>
    </inertial>
  </link>
  <link name="wrist">
    <visual>
      <origin rpy="0 0 0" xyz=".026 0 0"/>
      <geometry>
        <box size=".002 .020 .05788"/>
      </geometry>
    </visual>
    <visual>
      <origin rpy="0 0 0" xyz="0.006150000000000003 0 0.02794"/>
      <geometry>
        <box size="0.0377 .020 .002"/>
      </geometry>
    </visual>
    <visual>
      <origin rpy="0 0 0" xyz="0.006150000000000003 0 -0.02794"/>
      <geometry>
        <box size="0.0377 .020 .002"/>
      </geometry>
    </visual>
    <collision>
      <origin rpy="0 0 0" xyz=".026 0 0"/>
      <geometry>
        <box size=".002 .020 .05788"/>
      </geometry>
    </collision>
    <collision>
      <origin rpy="0 0 0" xyz="0.006150000000000003 0 0.02794"/>
      <geometry>
        <box size="0.0377 .020 .002"/>
      </geometry>
    </collision>
    <collision>
      <origin rpy="0 0 0" xyz="0.006150000000000003 0 -0.02794"/>
      <geometry>
        <box size="0.0377 .020 .002"/>
      </geometry>
    </collision>
    <inertial>
      <mass value="0.3"/>
      <inertia ixx="0.001" ixy="0.0" ixz="0.0" iyy="0.001" iyz="0.0" izz="0.001"/>
    </inertial>
  </link>
  <link name="gripper_base">
    <visual>
      <origin rpy="0 0 0" xyz=".014 0 0"/>
      <geometry>
        <box size=".014 .018 .05"/>
      </geometry>
    </visual>
    <visual>
      <origin rpy="0 1.570795 0" xyz="0 0 0"/>
      <geometry>
        <cylinder length=".014" radius=".009"/>
      </geometry>
    </visual>
    <collision>
      <origin rpy="0 0 0" xyz=".014 0 0"/>
      <geometry>
        <box size=".014 .018 .05"/>
      </geometry>
    </collision>
    <collision>
      <origin rpy="0 1.570795 0" xyz="0 0 0"/>
      <geometry>
        <!-- shorter to avoid numerical issues -->
        <cylinder length=".013" radius=".009"/>
      </geometry>
    </collision>
    <inertial>
      <mass value="0.3"/>
      <inertia ixx="0.001" ixy="0.0" ixz="0.0" iyy="0.001" iyz="0.0" izz="0.001"/>
    </inertial>
  </link>
  <link name="gripper_rightfinger">
    <visual>
      <origin rpy="0 0 0" xyz="0.0125 0 0"/>
      <geometry>
        <box size="0.025 0.021 0.00525"/>
      </geometry>
    </visual>
    <!-- <visual>
        <origin xyz="${gripper_width/2} 0 0" rpy="0 0 0"/>
        <geometry>
		      <box size="${gripper_width} ${gripper_height} ${gripper_height}"/>
        </geometry>
      </visual> -->
    <collision>
      <origin rpy="0 0 0" xyz="0.0125 0 0"/>
      <geometry>
        <box size="0.025 0.021 0.00525"/>
      </geometry>
      <surface>
        <friction>
          <ode>
            <mu>1.0</mu>
            <mu2>1.0</mu2>
          </ode>
        </friction>
      </surface>
    </collision>
    <inertial>
      <mass value="0.05"/>
      <inertia ixx="0.0001" ixy="0.0" ixz="0.0" iyy="0.0001" iyz="0.0" izz="0.0001"/>
    </inertial>
  </link>
  <link name="gripper_leftfinger">
    <visual>
      <origin rpy="0 0 0" xyz="0.0125 0 0"/>
      <geometry>
        <box size="0.025 0.021 0.00525"/>
      </geometry>
    </visual>
    <collision>
      <origin rpy="0 0 0" xyz="0.0125 0 0"/>
      <geometry>
        <box size="0.025 0.021 0.00525"/>
      </geometry>
      <surface>
        <friction>
          <ode>
            <mu>0.7</mu>
            <mu2>0.7</mu2>
          </ode>
        </friction>
      </surface>
    </collision>
    <inertial>
      <mass value="0.05"/>
      <inertia ixx="0.0001" ixy="0.0" ixz="0.0" iyy="0.0001" iyz="0.0" izz="0.0001"/>
    </inertial>
  </link>
  <link name="end"/>
  <link name="xaxis">
    <visual>
      <origin rpy="0 0 0" xyz="0.015 0 0"/>
      <geometry>
        <box size="0.03 0.001 0.001"/>
      </geometry>
    </visual>
  </link>
  <link name="yaxis">
    <visual>
      <origin rpy="0 0 0" xyz="0 0.015 0"/>
      <geometry>
        <box size="0.001 0.03 0.001"/>
      </geometry>
    </visual>
  </link>
  <link name="zaxis">
    <visual>
      <origin rpy="0 0 0" xyz="0 0 0.015"/>
      <geometry>
        <box size="0.001 0.001 0.03"/>
      </geometry>
    </visual>
  </link>
  <!-- joints -->
  <joint name="base_joint" type="fixed">
    <origin rpy="0 0 0" xyz="0 0 0"/>
    <parent link="world"/>
    <child link="base"/>
  </joint>
  <joint name="base_rotate" type="revolute">
    <origin rpy="0 0 0" xyz="0 0 0"/>
    <parent link="base"/>
    <child link="upper_base"/>
    <axis xyz="0 0 1"/>
    <limit effort="10" lower="-1.4" upper="1.4" velocity="3.67"/>
  </joint>
  <joint name="shoulder_tilt" type="revolute">
    <origin rpy="1.570795 -1.570795 0 " xyz="0 0 0.0762"/>
    <parent link="upper_base"/>
    <child link="upper_arm"/>
    <axis xyz="0 0 -1"/>
    <limit effort="10" lower="-1.2" upper="1.4" velocity="3.32"/>
  </joint>
  <joint name="elbow_tilt" type="revolute">
    <origin rpy="0 0 -1.570795" xyz="0.14605 0 0"/>
    <parent link="upper_arm"/>
    <child link="lower_arm"/>
    <axis xyz="0 0 -1"/>
    <limit effort="10" lower="-1.8" upper="1.7" velocity="3.67"/>
  </joint>
  <joint name="wrist_tilt" type="revolute">
    <origin rpy="0 0 0" xyz="0.187325 0 0"/>
    <parent link="lower_arm"/>
    <child link="wrist"/>
    <axis xyz="0 0 -1"/>
    <limit effort="10" lower="-1.9" upper="1.7" velocity="6.98"/>
  </joint>
  <joint name="wrist_rotate" type="revolute">
    <origin rpy="1.570795 0 0" xyz="0.034 0 0"/>
    <parent link="wrist"/>
    <child link="gripper_base"/>
    <axis xyz="1 0 0"/>
    <limit effort="10" lower="-2" upper="1.5" velocity="6.98"/>
  </joint>
  <joint name="open_gripperright" type="prismatic">
    <origin rpy="0 0 0" xyz="0.021 0 0.023"/>
    <origin rpy="0 0 0" xyz="0.021 0 0"/>
    <parent link="gripper_base"/>
    <child link="gripper_rightfinger"/>
    <axis xyz="0 0 1"/>
    <limit effort="100" lower="-0.03" upper="0.0" velocity="6.98"/>
  </joint>
  <joint name="open_gripperleft" type="prismatic">
    <origin rpy="0 0 0" xyz="0.021 0 -0.023"/>
    <parent link="gripper_base"/>
    <child link="gripper_leftfinger"/>
    <axis xyz="0 0 1"/>
    <limit effort="100" lower="0" upper="0.03" velocity="6.98"/>
  </joint>
  <joint name="end" type="fixed">
    <origin rpy="0 1.570795 0" xyz="0.034 0 0"/>
    <parent link="gripper_base"/>
    <child link="end"/>
  </joint>
  <joint name="axis1" type="fixed">
    <origin rpy="0 0 0" xyz="0 0 0"/>
    <parent link="end"/>
    <child link="xaxis"/>
  </joint>
  <joint name="axis2" type="fixed">
    <origin rpy="0 0 0" xyz="0 0 0"/>
    <parent link="end"/>
    <child link="yaxis"/>
  </joint>
  <joint name="axis3" type="fixed">
    <origin rpy="0 0 0" xyz="0 0 0"/>
    <parent link="end"/>
    <child link="zaxis"/>
  </joint>
  <gazebo>
    <plugin filename="libgazebo_ros_control.so" name="gazebo_ros_control">
      <robotSimType>gazebo_ros_control/DefaultRobotHWSim</robotSimType>
    </plugin>
  </gazebo>
  <gazebo reference="base">
    <material>Gazebo/DarkGrey</material>
    <self_collide>1</self_collide>
    <!-- <gazebo reference="${frame}"> -->
    <sensor name="base_collision_contact" type="contact">
      <update_rate>10.0</update_rate>
      <always_on>1</always_on>
      <contact>
        <collision>base_collision</collision>
      </contact>
      <plugin filename="libgazebo_ros_bumper.so" name="gazebo_ros_bumper_controller">
        <alwaysOn>true</alwaysOn>
        <updateRate>10.0</updateRate>
        <bumperTopicName>/collision</bumperTopicName>
        <frameName>base</frameName>
      </plugin>
    </sensor>
    <!-- </gazebo> -->
  </gazebo>
  <gazebo reference="upper_base">
    <material>Gazebo/LightGrey</material>
    <self_collide>1</self_collide>
    <!-- <gazebo reference="${frame}"> -->
    <sensor name="upper_base_collision_contact" type="contact">
      <update_rate>10.0</update_rate>
      <always_on>1</always_on>
      <contact>
        <collision>upper_base_collision</collision>
      </contact>
      <plugin filename="libgazebo_ros_bumper.so" name="gazebo_ros_bumper_controller">
        <alwaysOn>true</alwaysOn>
        <updateRate>10.0</updateRate>
        <bumperTopicName>/collision</bumperTopicName>
        <frameName>upper_base</frameName>
      </plugin>
    </sensor>
    <!-- </gazebo> -->
    <!-- <gazebo reference="${frame}"> -->
    <sensor name="upper_base_collision_1_contact" type="contact">
      <update_rate>10.0</update_rate>
      <always_on>1</always_on>
      <contact>
        <collision>upper_base_collision_1</collision>
      </contact>
      <plugin filename="libgazebo_ros_bumper.so" name="gazebo_ros_bumper_controller">
        <alwaysOn>true</alwaysOn>
        <updateRate>10.0</updateRate>
        <bumperTopicName>/collision</bumperTopicName>
        <frameName>upper_base</frameName>
      </plugin>
    </sensor>
    <!-- </gazebo> -->
  </gazebo>
  <gazebo reference="upper_arm">
    <material>Gazebo/DarkGrey</material>
    <self_collide>1</self_collide>
    <!-- <gazebo reference="${frame}"> -->
    <sensor name="upper_arm_collision_contact" type="contact">
      <update_rate>10.0</update_rate>
      <always_on>1</always_on>
      <contact>
        <collision>upper_arm_collision</collision>
      </contact>
      <plugin filename="libgazebo_ros_bumper.so" name="gazebo_ros_bumper_controller">
        <alwaysOn>true</alwaysOn>
        <updateRate>10.0</updateRate>
        <bumperTopicName>/collision</bumperTopicName>
        <frameName>upper_arm</frameName>
      </plugin>
    </sensor>
    <!-- </gazebo> -->
    <!-- <gazebo reference="${frame}"> -->
    <sensor name="upper_arm_collision_1_contact" type="contact">
      <update_rate>10.0</update_rate>
      <always_on>1</always_on>
      <contact>
        <collision>upper_arm_collision_1</collision>
      </contact>
      <plugin filename="libgazebo_ros_bumper.so" name="gazebo_ros_bumper_controller">
        <alwaysOn>true</alwaysOn>
        <updateRate>10.0</updateRate>
        <bumperTopicName>/collision</bumperTopicName>
        <frameName>upper_arm</frameName>
      </plugin>
    </sensor>
    <!-- </gazebo> -->
    <!-- <gazebo reference="${frame}"> -->
    <sensor name="upper_arm_collision_2_contact" type="contact">
      <update_rate>10.0</update_rate>
      <always_on>1</always_on>
      <contact>
        <collision>upper_arm_collision_2</collision>
      </contact>
      <plugin filename="libgazebo_ros_bumper.so" name="gazebo_ros_bumper_controller">
        <alwaysOn>true</alwaysOn>
        <updateRate>10.0</updateRate>
        <bumperTopicName>/collision</bumperTopicName>
        <frameName>upper_arm</frameName>
      </plugin>
    </sensor>
    <!-- </gazebo> -->
  </gazebo>
  <gazebo reference="lower_arm">
    <material>Gazebo/LightGrey</material>
    <self_collide>1</self_collide>
    <!-- <gazebo reference="${frame}"> -->
    <sensor name="lower_arm_collision_contact" type="contact">
      <update_rate>10.0</update_rate>
      <always_on>1</always_on>
      <contact>
        <collision>lower_arm_collision</collision>
      </contact>
      <plugin filename="libgazebo_ros_bumper.so" name="gazebo_ros_bumper_controller">
        <alwaysOn>true</alwaysOn>
        <updateRate>10.0</updateRate>
        <bumperTopicName>/collision</bumperTopicName>
        <frameName>lower_arm</frameName>
      </plugin>
    </sensor>
    <!-- </gazebo> -->
    <!-- <gazebo reference="${frame}"> -->
    <sensor name="lower_arm_collision_1_contact" type="contact">
      <update_rate>10.0</update_rate>
      <always_on>1</always_on>
      <contact>
        <collision>lower_arm_collision_1</collision>
      </contact>
      <plugin filename="libgazebo_ros_bumper.so" name="gazebo_ros_bumper_controller">
        <alwaysOn>true</alwaysOn>
        <updateRate>10.0</updateRate>
        <bumperTopicName>/collision</bumperTopicName>
        <frameName>lower_arm</frameName>
      </plugin>
    </sensor>
    <!-- </gazebo> -->
    <!-- <gazebo reference="${frame}"> -->
    <sensor name="lower_arm_collision_2_contact" type="contact">
      <update_rate>10.0</update_rate>
      <always_on>1</always_on>
      <contact>
        <collision>lower_arm_collision_2</collision>
      </contact>
      <plugin filename="libgazebo_ros_bumper.so" name="gazebo_ros_bumper_controller">
        <alwaysOn>true</alwaysOn>
        <updateRate>10.0</updateRate>
        <bumperTopicName>/collision</bumperTopicName>
        <frameName>lower_arm</frameName>
      </plugin>
    </sensor>
    <!-- </gazebo> -->
  </gazebo>
  <gazebo reference="wrist">
    <material>Gazebo/DarkGrey</material>
    <self_collide>1</self_collide>
    <!-- <gazebo reference="${frame}"> -->
    <sensor name="wrist_collision_contact" type="contact">
      <update_rate>10.0</update_rate>
      <always_on>1</always_on>
      <contact>
        <collision>wrist_collision</collision>
      </contact>
      <plugin filename="libgazebo_ros_bumper.so" name="gazebo_ros_bumper_controller">
        <alwaysOn>true</alwaysOn>
        <updateRate>10.0</updateRate>
        <bumperTopicName>/collision</bumperTopicName>
        <frameName>wrist</frameName>
      </plugin>
    </sensor>
    <!-- </gazebo> -->
    <!-- <gazebo reference="${frame}"> -->
    <sensor name="wrist_collision_1_contact" type="contact">
      <update_rate>10.0</update_rate>
      <always_on>1</always_on>
      <contact>
        <collision>wrist_collision_1</collision>
      </contact>
      <plugin filename="libgazebo_ros_bumper.so" name="gazebo_ros_bumper_controller">
        <alwaysOn>true</alwaysOn>
        <updateRate>10.0</updateRate>
        <bumperTopicName>/collision</bumperTopicName>
        <frameName>wrist</frameName>
      </plugin>
    </sensor>
    <!-- </gazebo> -->
    <!-- <gazebo reference="${frame}"> -->
    <sensor name="wrist_collision_2_contact" type="contact">
      <update_rate>10.0</update_rate>
      <always_on>1</always_on>
      <contact>
        <collision>wrist_collision_2</collision>
      </contact>
      <plugin filename="libgazebo_ros_bumper.so" name="gazebo_ros_bumper_controller">
        <alwaysOn>true</alwaysOn>
        <updateRate>10.0</updateRate>
        <bumperTopicName>/collision</bumperTopicName>
        <frameName>wrist</frameName>
      </plugin>
    </sensor>
    <!-- </gazebo> -->
  </gazebo>
  <gazebo reference="gripper_base">
    <material>Gazebo/LightGrey</material>
    <!-- <gazebo reference="${frame}"> -->
    <sensor name="gripper_base_collision_contact" type="contact">
      <update_rate>10.0</update_rate>
      <always_on>1</always_on>
      <contact>
        <collision>gripper_base_collision</collision>
      </contact>
      <plugin filename="libgazebo_ros_bumper.so" name="gazebo_ros_bumper_controller">
        <alwaysOn>true</alwaysOn>
        <updateRate>10.0</updateRate>
        <bumperTopicName>/collision</bumperTopicName>
        <frameName>gripper_base</frameName>
      </plugin>
    </sensor>
    <!-- </gazebo> -->
    <!-- <gazebo reference="${frame}"> -->
    <sensor name="gripper_base_collision_1_contact" type="contact">
      <update_rate>10.0</update_rate>
      <always_on>1</always_on>
      <contact>
        <collision>gripper_base_collision_1</collision>
      </contact>
      <plugin filename="libgazebo_ros_bumper.so" name="gazebo_ros_bumper_controller">
        <alwaysOn>true</alwaysOn>
        <updateRate>10.0</updateRate>
        <bumperTopicName>/collision</bumperTopicName>
        <frameName>gripper_base</frameName>
      </plugin>
    </sensor>
    <!-- </gazebo> -->
  </gazebo>
  <gazebo reference="gripper_leftfinger">
    <material>Gazebo/DarkGrey</material>
    <self_collide>1</self_collide>
    <turnGravityOff>true</turnGravityOff>
    <!-- <gazebo reference="${frame}"> -->
    <sensor name="gripper_leftfinger_collision_contact" type="contact">
      <update_rate>10.0</update_rate>
      <always_on>1</always_on>
      <contact>
        <collision>gripper_leftfinger_collision</collision>
      </contact>
      <plugin filename="libgazebo_ros_bumper.so" name="gazebo_ros_bumper_controller">
        <alwaysOn>true</alwaysOn>
        <updateRate>10.0</updateRate>
        <bumperTopicName>/collision</bumperTopicName>
        <frameName>gripper_leftfinger</frameName>
      </plugin>
    </sensor>
    <!-- </gazebo> -->
  </gazebo>
  <gazebo reference="gripper_rightfinger">
    <material>Gazebo/DarkGrey</material>
    <self_collide>1</self_collide>
    <turnGravityOff>true</turnGravityOff>
    <!-- <gazebo reference="${frame}"> -->
    <sensor name="gripper_rightfinger_collision_contact" type="contact">
      <update_rate>10.0</update_rate>
      <always_on>1</always_on>
      <contact>
        <collision>gripper_rightfinger_collision</collision>
      </contact>
      <plugin filename="libgazebo_ros_bumper.so" name="gazebo_ros_bumper_controller">
        <alwaysOn>true</alwaysOn>
        <updateRate>10.0</updateRate>
        <bumperTopicName>/collision</bumperTopicName>
        <frameName>gripper_rightfinger</frameName>
      </plugin>
    </sensor>
    <!-- </gazebo> -->
  </gazebo>
  <gazebo reference="end">
  </gazebo>
  <gazebo reference="xaxis">
    <material>Gazebo/RedTransparentOverlay</material>
  </gazebo>
  <gazebo reference="yaxis">
    <material>Gazebo/GreenTransparentOverlay</material>
  </gazebo>
  <gazebo reference="zaxis">
    <material>Gazebo/BlueTransparentOverlay</material>
  </gazebo>
  <!-- TO GET NAMES OF COLLISION: -->
  <!-- rosrun xacro xacro al5d_cad.xacro > temp.urdf -->
  <!-- gz sdf -p temp.urdf > temp.sdf -->
  <!-- Check names in temp.sdf -->
</robot>

