<?xml version="1.0"?>
<robot name="table" xmlns:xacro="http://ros.org/wiki/xacro">

    <transmission name="base_rotate_trans">
      <type>transmission_interface/SimpleTransmission</type>
      <joint name="base_rotate">
        <hardwareInterface>hardware_interface/VelocityJointInterface</hardwareInterface>
      </joint>
      <actuator name="base_rotate_motor">
        <hardwareInterface>hardware_interface/VelocityJointInterface</hardwareInterface>
        <mechanicalReduction>1</mechanicalReduction>
      </actuator>
    </transmission>

    <xacro:property name="base_radius" value="0.1" />

    <link name="world"></link>
    <link name="base">
      <visual>
        <origin xyz="0 0 ${.04/2}" rpy="0 0 0"/>
        <geometry>
          <cylinder length=".04" radius="${base_radius}"/>
        </geometry>
      </visual>
      <collision>
        <origin xyz="0 0 ${.04/2}" rpy="0 0 0"/>
        <geometry>
          <cylinder length=".04" radius="${base_radius}"/>
        </geometry>
      </collision>
      <inertial>
        <mass value="0.3"/>
        <inertia ixx="0.001" ixy="0.0" ixz="0.0" iyy="0.001" iyz="0.0" izz="0.001"/>
      </inertial>
    </link>
    <link name="upper_base">
      <visual>
	      <origin xyz="0 0 .045" rpy="0 0 0"/>
        <geometry>
          <cylinder length=".01" radius="${base_radius}"/>
        </geometry>
      </visual>
      <collision>
	      <origin xyz="0 0 .045" rpy="0 0 0"/>
        <geometry>
          <cylinder length=".01" radius="${base_radius}"/>
        </geometry>
      </collision>
      <inertial>
        <mass value="0.3"/>
        <inertia ixx="0.001" ixy="0.0" ixz="0.0" iyy="0.001" iyz="0.0" izz="0.001"/>
      </inertial>
    </link>




    <!-- joints -->
    <joint name="base_joint" type="fixed">
      <origin xyz="0 0 0" rpy="0 0 0"/>
      <parent link="world"/>
      <child link="base"/>
    </joint>
    <joint name="base_rotate" type="continuous">
      <origin xyz="0 0 0" rpy="0 0 0"/>
      <parent link="base"/>
      <child link="upper_base"/>
      <axis xyz="0 0 1"/>
      <!-- <limit lower="-1.4" upper="1.4" effort="10" velocity="3.67"/> -->
    </joint>

  <gazebo>
    <plugin name="gazebo_ros_control" filename="libgazebo_ros_control.so">
      <robotSimType>gazebo_ros_control/DefaultRobotHWSim</robotSimType>
    </plugin>
  </gazebo>


  <gazebo reference="base">
    <material>Gazebo/LightGrey</material>
  </gazebo>
  <gazebo reference="upper_base">
    <material>Gazebo/DarkGrey</material>
  </gazebo>

</robot>
